<?xml version="1.0" ?>
<sdf version="1.8">
<model name="smore" canonical_link="chasis_link">

  <!-- Back joint-->
  <joint name="back_wheel_link_joint" type="revolute">
    <pose relative_to="chasis_link">0.10390 0.05900 0.01019 0.00000 0.00000 0.00000</pose>
    <parent>chasis_link</parent>
    <child>back_link</child>
    <axis>
      <limit>
        <!-- Check actual ranges for back link-->
        <lower>-1.79769e+308</lower>
        <upper>1.79769e+308</upper>
      </limit>
      <xyz>1 0 0</xyz>
    </axis>
  </joint>
  <!-- Back joint-->

  <!-- Front wheel joint-->
  <joint name="front_wheel_link_joint" type="revolute">
    <pose relative_to="chasis_link">0.00000 -0.10251 -0.00000 1.57080 0.00000 0.00000</pose>
    <parent>chasis_link</parent>
    <child>front_wheel_link</child>
    <axis>
      <limit>
        <lower>-1.79769e+308</lower>
        <upper>1.79769e+308</upper>
      </limit>
      <xyz>0 0 1</xyz>
    </axis>
  </joint>
  <!-- Front wheel joint-->

  <!-- Left wheel joint-->
  <joint name="left_wheel_link_joint" type="revolute">
    <pose relative_to="chasis_link">0.11200 0.02822 0.00000 1.57080 1.41363 1.57080</pose>
    <parent>chasis_link</parent>
    <child>left_wheel_link</child>
    <axis>
      <limit>
        <lower>-1.79769e+308</lower>
        <upper>1.79769e+308</upper>
      </limit>
      <xyz>0 0 1</xyz>
    </axis>
  </joint>
  <!-- Left wheel joint-->


  <!-- Right wheel joint-->
  <joint name="right_wheel_link_joint" type="revolute">
    <pose relative_to="chasis_link">-0.11200 0.02822 0.00000 0.00000 1.57080 0.00000</pose>
    <parent>chasis_link</parent>
    <child>right_wheel_link</child>
    <axis>
      <limit>
        <lower>-1.79769e+308</lower>
        <upper>1.79769e+308</upper>
      </limit>
      <xyz>0 0 1</xyz>
    </axis>
  </joint>
  <!-- Right wheel joint-->

  <!-- Chasis link -->
  <link name="chasis_link">
    <pose>0.00000 0.00000 0.00000 0.00000 0.00000 0.00000</pose>
    <collision name="chasis_collision">
      <!--pose relative_to="chasis_link">0.00000 0.00000 0.00000 0.00000 0.00000 0.00000</pose-->
      <geometry>
        <mesh>
          <uri>/home/carlos/smore_ws/src/smore_project/ros_gz_example_description/models/smore/meshes/dae/Cube.dae</uri>
          <scale>0.10000 0.10000 0.10000</scale>
        </mesh>
      </geometry>
      <!--surface>
        <contact/>
      </surface-->
    </collision>
    <inertial>
      <inertia>
        <ixx>0.00100</ixx>
        <ixy>0.00000</ixy>
        <ixz>0.00000</ixz>
        <iyy>0.00100</iyy>
        <iyz>0.00000</iyz>
        <izz>0.00100</izz>
      </inertia>
      <mass>0.01000</mass>
    </inertial>
    <visual name="chasis">
      <material>
        <diffuse>0.80000 0.80000 0.80000 1.00000</diffuse>
        <specular>0.40000 0.40000 0.40000 0.49804</specular>
        <emissive>0.00000 0.00000 0.00000 1.00000</emissive>
      </material>
      <pose relative_to="chasis_link">0.00000 0.00000 0.00000 0.00000 0.00000 0.00000</pose>
      <geometry>
        <mesh>
          <uri>/home/carlos/smore_ws/src/smore_project/ros_gz_example_description/models/smore/meshes/dae/Cube.dae</uri>
          <scale>0.10000 0.10000 0.10000</scale>
        </mesh>
      </geometry>
    </visual>
  </link>
  <!-- Chasis link -->

  <!-- Back link -->
  <link name="back_link">
    <pose relative_to="chasis_link">0.10390 0.05900 0.01019 0.00000 0.00000 0.00000</pose>
    <collision name="back_collision">
      <!--pose relative_to="back_link">0.00028 -0.00040 -0.00019 0.00000 0.00000 0.00000</pose-->
      <geometry>
        <mesh>
          <uri>/home/carlos/smore_ws/src/smore_project/ros_gz_example_description/models/smore/meshes/dae/Cube.004.dae</uri>
          <scale>0.00300 0.08000 0.07000</scale>
        </mesh>
      </geometry>
      <!--surface>
        <contact/>
      </surface-->
    </collision>
    <visual name="back">
      <material>
        <diffuse>0.05882 0.80000 0.27843 1.00000</diffuse>
        <specular>0.02745 0.40000 0.13725 0.49804</specular>
        <emissive>0.00000 0.00000 0.00000 1.00000</emissive>
      </material>
      <pose relative_to="back_link">0.00000 0.00000 0.00000 0.00000 0.00000 0.00000</pose>
      <geometry>
        <mesh>
          <uri>/home/carlos/smore_ws/src/smore_project/ros_gz_example_description/models/smore/meshes/dae/Cube.004.dae</uri>
          <scale>0.00300 0.08000 0.07000</scale>
        </mesh>
      </geometry>
    </visual>
  </link>
  <!-- Back link -->

  <!-- Front wheel link-->
  <link name="front_wheel_link">
    <pose relative_to="chasis_link">0.00000 -0.10251 0.00000 1.57080 0.00000 0.00000</pose>
    <collision name="front_wheel_collision">
      <!--pose relative_to="front_wheel_link">0.00000 0.00000 0.00000 0.00000 0.00000 0.14096</pose-->
      <geometry>
        <cylinder>
          <radius>0.11000</radius>
          <length>0.00500</length>
        </cylinder>
      </geometry>
      <!--surface>
        <contact/>
      </surface-->
    </collision>
    <inertial>
      <inertia>
        <ixx>0.00003</ixx>
        <ixy>0.00000</ixy>
        <ixz>0.00000</ixz>
        <iyy>0.00006</iyy>
        <iyz>0.00000</iyz>
        <izz>0.00003</izz>
      </inertia>
      <!--pose relative_to="front_wheel_link">0.00000 0.00000 0.00000 0.00000 0.00000 0.00000</pose-->
      <mass>0.01000</mass>
    </inertial>
    <visual name="front_wheel">
      <material>
        <diffuse>0.83137 1.00000 0.40000 1.00000</diffuse>
        <specular>0.41569 0.49804 0.20000 0.49804</specular>
        <emissive>0.00000 0.00000 0.00000 1.00000</emissive>
      </material>
      <pose relative_to="front_wheel_link">-0.00000 -0.00000 -0.00000 0.00000 -0.00000 -0.14096</pose>
      <geometry>
        <cylinder>
          <radius>0.11000</radius>
          <length>0.00500</length>
        </cylinder>
      </geometry>
    </visual>
  </link>
  <!-- Front wheel link-->

  <!-- Left wheek link-->
  <link name="left_wheel_link">
    <pose relative_to="chasis_link">0.11200 0.02822 -0.00000 1.57080 1.41363 1.57080</pose>
    <collision name="left_wheel_collision">
      <!--pose relative_to="left_wheel_link">-0.00000 -0.00000 0.00000 -0.00000 -0.00000 -0.15717</pose-->
      <geometry>
        <cylinder>
          <radius>0.12000</radius>
          <length>0.00500</length>
        </cylinder>
      </geometry>
      <!--surface>
        <contact/>
      </surface-->
    </collision>
    <inertial>
      <inertia>
        <ixx>0.00007</ixx>
        <ixy>0.00000</ixy>
        <ixz>0.00000</ixz>
        <iyy>0.00004</iyy>
        <iyz>0.00000</iyz>
        <izz>0.00004</izz>
      </inertia>
      <!--pose relative_to="left_wheel_link">0.00000 0.00000 0.00000 0.00000 0.00000 0.00000</pose-->
      <mass>0.01000</mass>
    </inertial>
    <visual name="left_wheel">
      <material>
        <diffuse>0.00000 0.00000 1.00000 1.00000</diffuse>
        <specular>0.00000 0.00000 0.49804 0.49804</specular>
        <emissive>0.00000 0.00000 0.00000 1.00000</emissive>
      </material>
      <pose relative_to="left_wheel_link">0.00000 0.00000 0.00000 0.00000 0.00000 0.00000</pose>
      <geometry>
        <cylinder>
          <radius>0.12000</radius>
          <length>0.00500</length>
        </cylinder>
      </geometry>
    </visual>
  </link>
  <!-- Left wheek link-->

  <!-- Right wheek link-->
  <link name="right_wheel_link">
    <pose relative_to="chasis_link">-0.11200 0.02822 0.00000 0.00000 1.57080 0.00000</pose>
    <collision name="right_wheel_collision">
      <!--pose relative_to="right_wheel_link">0.00000 0.00000 -0.00000 -0.00000 -0.00000 0.00000</pose-->
      <geometry>
        <cylinder>
          <radius>0.12000</radius>
          <length>0.00500</length>
        </cylinder>
      </geometry>
      <!--surface>
        <contact/>
      </surface-->
    </collision>
    <inertial>
      <inertia>
        <ixx>0.00007</ixx>
        <ixy>0.00000</ixy>
        <ixz>0.00000</ixz>
        <iyy>0.00004</iyy>
        <iyz>0.00000</iyz>
        <izz>0.00004</izz>
      </inertia>
      <!--pose relative_to="right_wheel_link">0.00000 0.00000 0.00000 0.00000 0.00000 0.00000</pose-->
      <mass>0.01000</mass>
    </inertial>
    <visual name="right_wheel">
      <material>
        <diffuse>0.80000 0.00000 0.00000 1.00000</diffuse>
        <specular>0.40000 0.00000 0.00000 0.49804</specular>
        <emissive>0.00000 0.00000 0.00000 1.00000</emissive>
      </material>
      <pose relative_to="right_wheel_link">0.00000 0.00000 0.00000 0.00000 0.00000 0.00000</pose>
      <geometry>
        <cylinder>
          <radius>0.12000</radius>
          <length>0.00500</length>
        </cylinder>
      </geometry>
    </visual>
  </link>
  <!-- Right wheek link-->

  <plugin filename="ignition-gazebo-joint-position-controller-system" 
    name="ignition::gazebo::systems::JointPositionController">
    <joint_name>back_wheel_link_joint</joint_name>
    <p_gain>20.00000</p_gain>
    <i_gain>0.00000</i_gain>
    <d_gain>0.00000</d_gain>
  </plugin>

  <plugin filename="ignition-gazebo-joint-position-controller-system" 
    name="ignition::gazebo::systems::JointPositionController">
    <joint_name>front_wheel_link_joint</joint_name>
    <p_gain>20.00000</p_gain>
    <i_gain>0.00000</i_gain>
    <d_gain>0.00000</d_gain>
  </plugin>

  <plugin
    filename="libignition-gazebo-diff-drive-system.so"
    name="ignition::gazebo::systems::DiffDrive">
    <left_joint>left_wheel_link_joint</left_joint>
    <right_joint>right_wheel_link_joint</right_joint>
    <wheel_separation>0.2240</wheel_separation>
    <wheel_radius>0.12000</wheel_radius>
    <odom_publish_frequency>1</odom_publish_frequency>
    <topic>/smore/cmd_vel</topic>
  </plugin>

</model>
</sdf>